Workbook
Name покупатели: #REF!
Name Срез_Годы__Дата: #N/A
Name Срез_Годы__Дата1: #N/A
Name Срез_Годы__Дата2: #N/A
Name Срез_Годы__Дата3: #N/A
Name Срез_Кварталы__Дата: #N/A
Name Срез_Кварталы__Дата1: #N/A
Name Срез_магазин: #N/A
Name Срез_магазин1: #N/A
Name Срез_магазин2: #N/A
Name Срез_магазин3: #N/A
Name Срез_Месяцы__Дата: #N/A
Name Срез_Товар: #N/A
Name Срез_Товар1: #N/A

Sheet  КР задание
B1: В отдельных файлах приведены данные о работе магазинов игрушек
B3: Выбрать номер варианта в соответствие с номером по списку, выделить эту строку желтым в таблице.
B4: Скачать файл в свою папку, дав имя
B5: Имя файла : "Фамилия группа вариант" | C5: ПРИМЕР: Кошкин ФФ22-1 вариант 8
B7: Собрать все данные из папки Игрушки в этот файл с помощью Power Query. Вычислить необходимые по заданию показатели, если надо. | D7: Если данные собраны неправильно, дальнейшая проверка не производится
B8: Построить 2 информационные панели, отражающие деятельность магазинов.
B9: Состав панели определяется вариантом. Можно добавлять свои элементы. | D9: Все финансовые данные должны быть указаны с точностью до 1 рубля
D10: Все количественные данные должны быть указаны с точностью до 1 штуки
B11: Одна панель строится с использованием Excel | D11: Все процентные показатели должны быть указаны с точностью до 0,01%
B14: Аналогичная панель строится в DataLens
B16: ссылку на ДБ в DataLens положить сюда : | C16: https://datalens.yandex/j15w3poobhta3
B21: Выполненную работу :
B22: положить в личную папку на диске О этот файл с выполненным в нём заданием
B23: не позже времени, предусмотренного регламентом
B25: объект | C25: Баллы
B26: сбор данных, вычисления | C26: 1
B27: срезы: наличие, правильное подключение | C27: 1
B28: графики: соблюдение правил | C28: 1
B29: 1 KPI, 2 KPI, контрольный вопрос | C29: 1
B30: компоновка Дашборда, дизайн | C30: 1
C31: 5

Sheet вариант-номер по списку
A1: № по списку | B1: 1 обязательный график - динамика | C1: 2 обязательный график - рейтинг | D1: 3 обязательный график - доля | E1: 4 обязательный график для Excel | F1: 4 обязательный график для DataLensl | G1: 1 KPI | H1: 2 KPI для Excel | I1: 2 для DataLensl Вкладка с таблицей | J1: контрольный вопрос
A2: 3 | B2: динамика продаж (выручка) | C2: магазинов по количеству продаж | D2: менеджеров в общей выручке | E2: ТОП-5 товаров по числу продаж | F2: структура числа продаж магазинов по менеджерам | G2: общая выручка, число продаж, средний чек сделки | H2: лучший товар по выручке с указанием названия, выручки и плана | I2: магазины, менеджеры, товары по выручке, числу продаж, среднему чеку | J2: Какова доля выручки магазина Детский мир в 2020 году по товату Домик для кукол ?
L3: 3.1 Определите на какую сумму в заданный отчетный период был продан указанный в задании товар
L4: 3.2 Определите, какую долю эта сумма составляет от общего объема выручки за этот период
L5: 3.3 Выведите фамилию менеджера, получившего за этот период наибольшую выручку от продажи указанного товара и эту сумму через срез.

Sheet прайс
B2: Товар | C2: Цена за шт., руб
B3: Медведь рыжий | C3: 3100
B4: Медведь белый | C4: 2200
B5: Медведь мягкий | C5: 2560
B6: Мозаика | C6: 680
B7: Кукла Маша | C7: 1788
B8: Кукла Даша | C8: 2450
B9: Кукла Аленка | C9: 4500
B10: Конструктор малый | C10: 1600
B11: Конструктор большой | C11: 3796
B12: Конструктор строительный | C12: 4455
B13: Домик для куклы сборный | C13: 2000
B14: Домик для куклы с мебелью | C14: 5789
B15: Домик для куклы розовый | C15: 3470

Sheet Итоговая
A1: Дата | B1: Товар | C1: количество_единиц_товара | D1: выручка | E1: менеджер | F1: магазин | G1: Товар | H1: Цена_за_шт.,_руб | J1: Сумма_по_полю_выручка | K1: Названия столбцов
A2: 42382.22 | B2: Мозаика | C2: 13 | D2: =VLOOKUP(Добавить1[[#This Row],[Товар]],$G$1:$H$14,2,0)*Добавить1[[#This Row],[количество_единиц_товара]] -> 8840 | E2: Иванисов Максим | F2: Детки-конфетки | G2: Медведь рыжий | H2: 3100 | J2: Названия_строк | K2: Детки-конфетки | L2: Детский_мир | M2: Машенька | N2: Мир_детства | O2: Общий_итог
A3: 42392.014 | B3: Конструктор строительный | C3: 14 | D3: =VLOOKUP(Добавить1[[#This Row],[Товар]],$G$1:$H$14,2,0)*Добавить1[[#This Row],[количество_единиц_товара]] -> 62370 | E3: Немченко Дарья | F3: Детки-конфетки | G3: Медведь белый | H3: 2200 | J3: 2016 | K3: 3058599 | L3: 2373098 | M3: 2244450 | N3: 2373303 | O3: 10049450
A4: 42394.635 | B4: Медведь мягкий | C4: 38 | D4: =VLOOKUP(Добавить1[[#This Row],[Товар]],$G$1:$H$14,2,0)*Добавить1[[#This Row],[количество_единиц_товара]] -> 97280 | E4: Иванисов Максим | F4: Детки-конфетки | G4: Медведь мягкий | H4: 2560 | J4: 2017 | K4: 2936869 | L4: 2571584 | M4: 2423035 | N4: 2329470 | O4: 10260958
A5: 42396.053 | B5: Конструктор строительный | C5: 35 | D5: =VLOOKUP(Добавить1[[#This Row],[Товар]],$G$1:$H$14,2,0)*Добавить1[[#This Row],[количество_единиц_товара]] -> 155925 | E5: Иванисов Максим | F5: Детки-конфетки | G5: Мозаика | H5: 680 | J5: 2018 | K5: 2156012 | L5: 2656881 | M5: 2553694 | N5: 2481183 | O5: 9847770
A6: 42403.714 | B6: Кукла Маша | C6: 29 | D6: =VLOOKUP(Добавить1[[#This Row],[Товар]],$G$1:$H$14,2,0)*Добавить1[[#This Row],[количество_единиц_товара]] -> 51852 | E6: Загорский Глеб | F6: Детки-конфетки | G6: Кукла Маша | H6: 1788 | J6: 2019 | K6: 2513033 | L6: 1990374 | M6: 2680357 | N6: 2030807 | O6: 9214571
A7: 42407.948 | B7: Медведь мягкий | C7: 26 | D7: =VLOOKUP(Добавить1[[#This Row],[Товар]],$G$1:$H$14,2,0)*Добавить1[[#This Row],[количество_единиц_товара]] -> 66560 | E7: Загорский Глеб | F7: Детки-конфетки | G7: Кукла Даша | H7: 2450 | J7: 2020 | K7: 2218580 | L7: 2710371 | M7: 3387188 | N7: 2385127 | O7: 10701266
A8: 42422.93 | B8: Мозаика | C8: 23 | D8: =VLOOKUP(Добавить1[[#This Row],[Товар]],$G$1:$H$14,2,0)*Добавить1[[#This Row],[количество_единиц_товара]] -> 15640 | E8: Загорский Глеб | F8: Детки-конфетки | G8: Кукла Аленка | H8: 4500 | J8: 2021 | K8: 1542632 | L8: 1974241 | M8: 1356046 | N8: 2342699 | O8: 7215618
A9: 42430.915 | B9: Конструктор малый | C9: 22 | D9: =VLOOKUP(Добавить1[[#This Row],[Товар]],$G$1:$H$14,2,0)*Добавить1[[#This Row],[количество_единиц_товара]] -> 35200 | E9: Загорский Глеб | F9: Детки-конфетки | G9: Конструктор малый | H9: 1600 | J9: Общий_итог | K9: 14425725 | L9: 14276549 | M9: 14644770 | N9: 13942589 | O9: 57289633
A10: 42439.666 | B10: Медведь рыжий | C10: 29 | D10: =VLOOKUP(Добавить1[[#This Row],[Товар]],$G$1:$H$14,2,0)*Добавить1[[#This Row],[количество_единиц_товара]] -> 89900 | E10: Загорский Глеб | F10: Детки-конфетки | G10: Конструктор большой | H10: 3796
A11: 42467.986 | B11: Конструктор малый | C11: 10 | D11: =VLOOKUP(Добавить1[[#This Row],[Товар]],$G$1:$H$14,2,0)*Добавить1[[#This Row],[количество_единиц_товара]] -> 16000 | E11: Загорский Глеб | F11: Детки-конфетки | G11: Конструктор строительный | H11: 4455
A12: 42475.27 | B12: Мозаика | C12: 39 | D12: =VLOOKUP(Добавить1[[#This Row],[Товар]],$G$1:$H$14,2,0)*Добавить1[[#This Row],[количество_единиц_товара]] -> 26520 | E12: Загорский Глеб | F12: Детки-конфетки | G12: Домик для куклы сборный | H12: 2000
A13: 42479.66 | B13: Мозаика | C13: 22 | D13: =VLOOKUP(Добавить1[[#This Row],[Товар]],$G$1:$H$14,2,0)*Добавить1[[#This Row],[количество_единиц_товара]] -> 14960 | E13: Загорский Глеб | F13: Детки-конфетки | G13: Домик для куклы с мебелью | H13: 5789
A14: 42480.697 | B14: Домик для куклы сборный | C14: 14 | D14: =VLOOKUP(Добавить1[[#This Row],[Товар]],$G$1:$H$14,2,0)*Добавить1[[#This Row],[количество_единиц_товара]] -> 28000 | E14: Иванисов Максим | F14: Детки-конфетки | G14: Домик для куклы розовый | H14: 3470
A15: 42483.325 | B15: Кукла Даша | C15: 28 | D15: =VLOOKUP(Добавить1[[#This Row],[Товар]],$G$1:$H$14,2,0)*Добавить1[[#This Row],[количество_единиц_товара]] -> 68600 | E15: Немченко Дарья | F15: Детки-конфетки
A16: 42495.657 | B16: Медведь рыжий | C16: 22 | D16: =VLOOKUP(Добавить1[[#This Row],[Товар]],$G$1:$H$14,2,0)*Добавить1[[#This Row],[количество_единиц_товара]] -> 68200 | E16: Иванисов Максим | F16: Детки-конфетки
A17: 42513.539 | B17: Медведь белый | C17: 22 | D17: =VLOOKUP(Добавить1[[#This Row],[Товар]],$G$1:$H$14,2,0)*Добавить1[[#This Row],[количество_единиц_товара]] -> 48400 | E17: Иванисов Максим | F17: Детки-конфетки
A18: 42524.252 | B18: Медведь рыжий | C18: 39 | D18: =VLOOKUP(Добавить1[[#This Row],[Товар]],$G$1:$H$14,2,0)*Добавить1[[#This Row],[количество_единиц_товара]] -> 120900 | E18: Немченко Дарья | F18: Детки-конфетки
A19: 42532.015 | B19: Домик для куклы розовый | C19: 12 | D19: =VLOOKUP(Добавить1[[#This Row],[Товар]],$G$1:$H$14,2,0)*Добавить1[[#This Row],[количество_единиц_товара]] -> 41640 | E19: Иванисов Максим | F19: Детки-конфетки
A20: 42536.244 | B20: Медведь мягкий | C20: 16 | D20: =VLOOKUP(Добавить1[[#This Row],[Товар]],$G$1:$H$14,2,0)*Добавить1[[#This Row],[количество_единиц_товара]] -> 40960 | E20: Иванисов Максим | F20: Детки-конфетки
A21: 42540.788 | B21: Конструктор строительный | C21: 37 | D21: =VLOOKUP(Добавить1[[#This Row],[Товар]],$G$1:$H$14,2,0)*Добавить1[[#This Row],[количество_единиц_товара]] -> 164835 | E21: Немченко Дарья | F21: Детки-конфетки
A22: 42551.354 | B22: Кукла Даша | C22: 27 | D22: =VLOOKUP(Добавить1[[#This Row],[Товар]],$G$1:$H$14,2,0)*Добавить1[[#This Row],[количество_единиц_товара]] -> 66150 | E22: Иванисов Максим | F22: Детки-конфетки
A23: 42558.12 | B23: Домик для куклы с мебелью | C23: 36 | D23: =VLOOKUP(Добавить1[[#This Row],[Товар]],$G$1:$H$14,2,0)*Добавить1[[#This Row],[количество_единиц_товара]] -> 208404 | E23: Иванисов Максим | F23: Детки-конфетки
A24: 42558.87 | B24: Кукла Даша | C24: 37 | D24: =VLOOKUP(Добавить1[[#This Row],[Товар]],$G$1:$H$14,2,0)*Добавить1[[#This Row],[количество_единиц_товара]] -> 90650 | E24: Немченко Дарья | F24: Детки-конфетки
A25: 42567.749 | B25: Домик для куклы с мебелью | C25: 17 | D25: =VLOOKUP(Добавить1[[#This Row],[Товар]],$G$1:$H$14,2,0)*Добавить1[[#This Row],[количество_единиц_товара]] -> 98413 | E25: Иванисов Максим | F25: Детки-конфетки
A26: 42582.422 | B26: Домик для куклы сборный | C26: 39 | D26: =VLOOKUP(Добавить1[[#This Row],[Товар]],$G$1:$H$14,2,0)*Добавить1[[#This Row],[количество_единиц_товара]] -> 78000 | E26: Иванисов Максим | F26: Детки-конфетки
... A51: 42815.676 | B51: Конструктор строительный | C51: 12 | D51: =VLOOKUP(Добавить1[[#This Row],[Товар]],$G$1:$H$14,2,0)*Добавить1[[#This Row],[количество_единиц_товара]] -> 53460 | E51: Загорский Глеб | F51: Детки-конфетки
A52: 42816.997 | B52: Медведь мягкий | C52: 15 | D52: =VLOOKUP(Добавить1[[#This Row],[Товар]],$G$1:$H$14,2,0)*Добавить1[[#This Row],[количество_единиц_товара]] -> 38400 | E52: Иванисов Максим | F52: Детки-конфетки | N52: Названия строк | O52: Сумма по полю количество единиц товара
A53: 42817.949 | B53: Медведь рыжий | C53: 17 | D53: =VLOOKUP(Добавить1[[#This Row],[Товар]],$G$1:$H$14,2,0)*Добавить1[[#This Row],[количество_единиц_товара]] -> 52700 | E53: Немченко Дарья | F53: Детки-конфетки | N53: Мир детства | O53: 5377
A54: 42827.337 | B54: Домик для куклы с мебелью | C54: 23 | D54: =VLOOKUP(Добавить1[[#This Row],[Товар]],$G$1:$H$14,2,0)*Добавить1[[#This Row],[количество_единиц_товара]] -> 133147 | E54: Немченко Дарья | F54: Детки-конфетки | N54: Детский мир | O54: 5497
A55: 42830.805 | B55: Кукла Аленка | C55: 37 | D55: =VLOOKUP(Добавить1[[#This Row],[Товар]],$G$1:$H$14,2,0)*Добавить1[[#This Row],[количество_единиц_товара]] -> 166500 | E55: Немченко Дарья | F55: Детки-конфетки | N55: Детки-конфетки | O55: 5528
A56: 42833.667 | B56: Медведь белый | C56: 33 | D56: =VLOOKUP(Добавить1[[#This Row],[Товар]],$G$1:$H$14,2,0)*Добавить1[[#This Row],[количество_единиц_товара]] -> 72600 | E56: Немченко Дарья | F56: Детки-конфетки | N56: Машенька | O56: 5588
A57: 42838.313 | B57: Медведь рыжий | C57: 23 | D57: =VLOOKUP(Добавить1[[#This Row],[Товар]],$G$1:$H$14,2,0)*Добавить1[[#This Row],[количество_единиц_товара]] -> 71300 | E57: Немченко Дарья | F57: Детки-конфетки | N57: Общий итог | O57: 21990
A58: 42841.78 | B58: Кукла Даша | C58: 23 | D58: =VLOOKUP(Добавить1[[#This Row],[Товар]],$G$1:$H$14,2,0)*Добавить1[[#This Row],[количество_единиц_товара]] -> 56350 | E58: Немченко Дарья | F58: Детки-конфетки
A59: 42845.75 | B59: Медведь мягкий | C59: 11 | D59: =VLOOKUP(Добавить1[[#This Row],[Товар]],$G$1:$H$14,2,0)*Добавить1[[#This Row],[количество_единиц_товара]] -> 28160 | E59: Немченко Дарья | F59: Детки-конфетки
A60: 42846.468 | B60: Медведь рыжий | C60: 11 | D60: =VLOOKUP(Добавить1[[#This Row],[Товар]],$G$1:$H$14,2,0)*Добавить1[[#This Row],[количество_единиц_товара]] -> 34100 | E60: Немченко Дарья | F60: Детки-конфетки
A61: 42865.513 | B61: Домик для куклы сборный | C61: 37 | D61: =VLOOKUP(Добавить1[[#This Row],[Товар]],$G$1:$H$14,2,0)*Добавить1[[#This Row],[количество_единиц_товара]] -> 74000 | E61: Иванисов Максим | F61: Детки-конфетки
A62: 42875.664 | B62: Конструктор строительный | C62: 22 | D62: =VLOOKUP(Добавить1[[#This Row],[Товар]],$G$1:$H$14,2,0)*Добавить1[[#This Row],[количество_единиц_товара]] -> 98010 | E62: Иванисов Максим | F62: Детки-конфетки
A63: 42879.179 | B63: Конструктор строительный | C63: 32 | D63: =VLOOKUP(Добавить1[[#This Row],[Товар]],$G$1:$H$14,2,0)*Добавить1[[#This Row],[количество_единиц_товара]] -> 142560 | E63: Загорский Глеб | F63: Детки-конфетки
A64: 42885.423 | B64: Медведь мягкий | C64: 39 | D64: =VLOOKUP(Добавить1[[#This Row],[Товар]],$G$1:$H$14,2,0)*Добавить1[[#This Row],[количество_единиц_товара]] -> 99840 | E64: Загорский Глеб | F64: Детки-конфетки
...

Sheet Лист1
A1: Дата | B1: Товар | C1: количество_единиц_товара | D1: выручка | E1: менеджер | F1: магазин
A2: 42382.22 | B2: Мозаика | C2: 13 | D2: =VLOOKUP(Добавить18[[#This Row],[Товар]],Итоговая!$G$1:$H$14,2,0)*Добавить18[[#This Row],[количество_единиц_товара]] -> 8840 | E2: Иванисов Максим | F2: Детки-конфетки
A3: 42392.014 | B3: Конструктор строительный | C3: 14 | D3: =VLOOKUP(Добавить18[[#This Row],[Товар]],Итоговая!$G$1:$H$14,2,0)*Добавить18[[#This Row],[количество_единиц_товара]] -> 62370 | E3: Немченко Дарья | F3: Детки-конфетки
A4: 42394.635 | B4: Медведь мягкий | C4: 38 | D4: =VLOOKUP(Добавить18[[#This Row],[Товар]],Итоговая!$G$1:$H$14,2,0)*Добавить18[[#This Row],[количество_единиц_товара]] -> 97280 | E4: Иванисов Максим | F4: Детки-конфетки
A5: 42396.053 | B5: Конструктор строительный | C5: 35 | D5: =VLOOKUP(Добавить18[[#This Row],[Товар]],Итоговая!$G$1:$H$14,2,0)*Добавить18[[#This Row],[количество_единиц_товара]] -> 155925 | E5: Иванисов Максим | F5: Детки-конфетки
A6: 42403.714 | B6: Кукла Маша | C6: 29 | D6: =VLOOKUP(Добавить18[[#This Row],[Товар]],Итоговая!$G$1:$H$14,2,0)*Добавить18[[#This Row],[количество_единиц_товара]] -> 51852 | E6: Загорский Глеб | F6: Детки-конфетки
A7: 42407.948 | B7: Медведь мягкий | C7: 26 | D7: =VLOOKUP(Добавить18[[#This Row],[Товар]],Итоговая!$G$1:$H$14,2,0)*Добавить18[[#This Row],[количество_единиц_товара]] -> 66560 | E7: Загорский Глеб | F7: Детки-конфетки
A8: 42422.93 | B8: Мозаика | C8: 23 | D8: =VLOOKUP(Добавить18[[#This Row],[Товар]],Итоговая!$G$1:$H$14,2,0)*Добавить18[[#This Row],[количество_единиц_товара]] -> 15640 | E8: Загорский Глеб | F8: Детки-конфетки
A9: 42430.915 | B9: Конструктор малый | C9: 22 | D9: =VLOOKUP(Добавить18[[#This Row],[Товар]],Итоговая!$G$1:$H$14,2,0)*Добавить18[[#This Row],[количество_единиц_товара]] -> 35200 | E9: Загорский Глеб | F9: Детки-конфетки
A10: 42439.666 | B10: Медведь рыжий | C10: 29 | D10: =VLOOKUP(Добавить18[[#This Row],[Товар]],Итоговая!$G$1:$H$14,2,0)*Добавить18[[#This Row],[количество_единиц_товара]] -> 89900 | E10: Загорский Глеб | F10: Детки-конфетки
A11: 42467.986 | B11: Конструктор малый | C11: 10 | D11: =VLOOKUP(Добавить18[[#This Row],[Товар]],Итоговая!$G$1:$H$14,2,0)*Добавить18[[#This Row],[количество_единиц_товара]] -> 16000 | E11: Загорский Глеб | F11: Детки-конфетки
A12: 42475.27 | B12: Мозаика | C12: 39 | D12: =VLOOKUP(Добавить18[[#This Row],[Товар]],Итоговая!$G$1:$H$14,2,0)*Добавить18[[#This Row],[количество_единиц_товара]] -> 26520 | E12: Загорский Глеб | F12: Детки-конфетки
A13: 42479.66 | B13: Мозаика | C13: 22 | D13: =VLOOKUP(Добавить18[[#This Row],[Товар]],Итоговая!$G$1:$H$14,2,0)*Добавить18[[#This Row],[количество_единиц_товара]] -> 14960 | E13: Загорский Глеб | F13: Детки-конфетки
... A900: 44469.988 | B900: Медведь мягкий | C900: 22 | D900: =VLOOKUP(Добавить18[[#This Row],[Товар]],Итоговая!$G$1:$H$14,2,0)*Добавить18[[#This Row],[количество_единиц_товара]] -> 56320 | E900: Зайцев Кирилл | F900: Мир детства

Sheet Детки-конфетки
A1: Дата | B1: Товар | C1: количество единиц товара | D1: выручка | E1: менеджер
A2: 42382.22 | B2: Мозаика | C2: 13 | E2: Иванисов Максим
A3: 42392.014 | B3: Конструктор строительный | C3: 14 | E3: Немченко Дарья
A4: 42394.635 | B4: Медведь мягкий | C4: 38 | E4: Иванисов Максим
A5: 42396.053 | B5: Конструктор строительный | C5: 35 | E5: Иванисов Максим
A6: 42403.714 | B6: Кукла Маша | C6: 29 | E6: Загорский Глеб
A7: 42407.948 | B7: Медведь мягкий | C7: 26 | E7: Загорский Глеб
A8: 42422.93 | B8: Мозаика | C8: 23 | E8: Загорский Глеб
A9: 42430.915 | B9: Конструктор малый | C9: 22 | E9: Загорский Глеб
A10: 42439.666 | B10: Медведь рыжий | C10: 29 | E10: Загорский Глеб
A11: 42467.986 | B11: Конструктор малый | C11: 10 | E11: Загорский Глеб
A12: 42475.27 | B12: Мозаика | C12: 39 | E12: Загорский Глеб
A13: 42479.66 | B13: Мозаика | C13: 22 | E13: Загорский Глеб
... A224: 44449.897 | B224: Домик для куклы розовый | C224: 30 | E224: Загорский Глеб

Sheet Детский мир
A1: Дата | B1: Товар | C1: количество единиц товара | D1: выручка | E1: менеджер
A2: 42385.033 | B2: Конструктор малый | C2: 35 | E2: Родинов Илья
A3: 42395.552 | B3: Медведь мягкий | C3: 10 | E3: Жиркова Ольга
A4: 42398.774 | B4: Домик для куклы сборный | C4: 30 | E4: Усачев Михаил
A5: 42405.455 | B5: Мозаика | C5: 11 | E5: Жиркова Ольга
A6: 42408.954 | B6: Медведь мягкий | C6: 31 | E6: Родинов Илья
A7: 42412.763 | B7: Мозаика | C7: 32 | E7: Усачев Михаил
A8: 42426.187 | B8: Мозаика | C8: 36 | E8: Жиркова Ольга
A9: 42440.23 | B9: Медведь рыжий | C9: 18 | E9: Усачев Михаил
A10: 42451.972 | B10: Медведь белый | C10: 37 | E10: Усачев Михаил
A11: 42464.156 | B11: Кукла Маша | C11: 40 | E11: Родинов Илья
A12: 42467.112 | B12: Домик для куклы сборный | C12: 14 | E12: Жиркова Ольга
A13: 42482.85 | B13: Конструктор малый | C13: 24 | E13: Родинов Илья
... A232: 44428.354 | B232: Кукла Даша | C232: 22 | E232: Жиркова Ольга

Sheet Машенька
A1: Дата | B1: Товар | C1: количество единиц | D1: выручка | E1: менеджер | F1: Column6 | G1: Column7 | H1: Column8 | I1: Column9 | J1: Column10 | K1: Column11
A2: 42404.649 | B2: Кукла Даша | C2: 14 | E2: Жиркова Ольга
A3: 42413.08 | B3: Домик для куклы розовый | C3: 19 | E3: Родинов Илья
A4: 42417.574 | B4: Конструктор строительный | C4: 26 | E4: Родинов Илья
A5: 42418.724 | B5: Мозаика | C5: 26 | E5: Родинов Илья
A6: 42429.497 | B6: Мозаика | C6: 25 | E6: Родинов Илья
A7: 42438.528 | B7: Мозаика | C7: 24 | E7: Родинов Илья
A8: 42444.703 | B8: Домик для куклы сборный | C8: 17 | E8: Родинов Илья
A9: 42449.184 | B9: Мозаика | C9: 21 | E9: Родинов Илья
A10: 42457.657 | B10: Мозаика | C10: 29 | E10: Родинов Илья
A11: 42460.788 | B11: Домик для куклы сборный | C11: 23 | E11: Родинов Илья
A12: 42462.718 | B12: Мозаика | C12: 14 | E12: Родинов Илья
A13: 42472.484 | B13: Конструктор малый | C13: 22 | E13: Родинов Илья
... A226: 44436.089 | B226: Медведь белый | C226: 11 | E226: Жиркова Ольга

Sheet Мир детства
A1: Дата | B1: Товар | C1: количество единиц товара | D1: выручка | E1: менеджер
A2: 42386.497 | B2: Домик для куклы сборный | C2: 25 | E2: Зайцев Кирилл
A3: 42389.494 | B3: Кукла Маша | C3: 11 | E3: Белоусова Валерия
A4: 42390.648 | B4: Медведь мягкий | C4: 18 | E4: Ткачева Наталья
A5: 42400.337 | B5: Медведь белый | C5: 38 | E5: Белоусова Валерия
A6: 42423.845 | B6: Домик для куклы с мебелью | C6: 29 | E6: Ткачева Наталья
A7: 42435.165 | B7: Медведь мягкий | C7: 25 | E7: Белоусова Валерия
A8: 42456.288 | B8: Конструктор большой | C8: 35 | E8: Белоусова Валерия
A9: 42474.675 | B9: Мозаика | C9: 30 | E9: Зайцев Кирилл
A10: 42490.471 | B10: Домик для куклы розовый | C10: 21 | E10: Белоусова Валерия
A11: 42496.198 | B11: Медведь белый | C11: 34 | E11: Зайцев Кирилл
A12: 42497.076 | B12: Конструктор строительный | C12: 20 | E12: Зайцев Кирилл
A13: 42515.363 | B13: Кукла Аленка | C13: 33 | E13: Зайцев Кирилл
... A221: 44469.988 | B221: Медведь мягкий | C221: 22 | E221: Зайцев Кирилл
